
2020-05-25 09:26:49,522 INFO: errors [in /Users/nisp78/Desktop/01_fyyur/starter_code/app.py:540]
2020-05-25 09:41:55,905 INFO: errors [in /Users/nisp78/Desktop/01_fyyur/starter_code/app.py:540]
2020-05-25 09:54:58,408 INFO: errors [in /Users/nisp78/Desktop/01_fyyur/starter_code/app.py:545]
2020-05-25 10:21:06,279 INFO: errors [in /Users/nisp78/Desktop/01_fyyur/starter_code/app.py:545]
2020-05-25 12:54:30,594 INFO: errors [in /Users/nisp78/Desktop/01_fyyur/starter_code/app.py:545]
2020-05-25 13:17:01,680 INFO: errors [in /Users/nisp78/Desktop/01_fyyur/starter_code/app.py:545]
2020-05-25 13:18:06,116 INFO: errors [in /Users/nisp78/Desktop/01_fyyur/starter_code/app.py:545]
2020-05-25 13:22:11,116 INFO: errors [in /Users/nisp78/Desktop/01_fyyur/starter_code/app.py:545]
2020-05-25 13:28:12,378 INFO: errors [in /Users/nisp78/Desktop/01_fyyur/starter_code/app.py:545]
2020-05-25 13:29:00,167 INFO: errors [in /Users/nisp78/Desktop/01_fyyur/starter_code/app.py:545]
2020-05-25 14:11:49,260 INFO: errors [in /Users/nisp78/Desktop/01_fyyur/starter_code/app.py:545]
2020-05-25 14:14:26,745 INFO: errors [in /Users/nisp78/Desktop/01_fyyur/starter_code/app.py:545]
2020-05-25 14:23:22,149 INFO: errors [in /Users/nisp78/Desktop/01_fyyur/starter_code/app.py:545]
2020-05-25 15:04:08,553 INFO: errors [in /Users/nisp78/Desktop/01_fyyur/starter_code/app.py:545]
2020-05-25 15:04:23,899 INFO: errors [in /Users/nisp78/Desktop/01_fyyur/starter_code/app.py:545]
2020-05-25 15:06:38,571 INFO: errors [in /Users/nisp78/Desktop/01_fyyur/starter_code/app.py:545]
2020-05-25 15:09:40,380 INFO: errors [in /Users/nisp78/Desktop/01_fyyur/starter_code/app.py:545]
2020-05-25 15:18:45,261 INFO: errors [in /Users/nisp78/Desktop/01_fyyur/starter_code/app.py:545]
2020-05-25 15:27:34,008 INFO: errors [in /Users/nisp78/Desktop/01_fyyur/starter_code/app.py:545]
2020-05-25 15:32:06,844 INFO: errors [in /Users/nisp78/Desktop/01_fyyur/starter_code/app.py:545]
2020-05-25 15:32:28,921 INFO: errors [in /Users/nisp78/Desktop/01_fyyur/starter_code/app.py:545]
2020-05-25 15:33:40,156 INFO: errors [in /Users/nisp78/Desktop/01_fyyur/starter_code/app.py:545]
2020-05-25 15:38:06,217 INFO: errors [in /Users/nisp78/Desktop/01_fyyur/starter_code/app.py:545]
2020-05-25 15:39:05,252 INFO: errors [in /Users/nisp78/Desktop/01_fyyur/starter_code/app.py:545]
2020-05-25 15:42:26,263 INFO: errors [in /Users/nisp78/Desktop/01_fyyur/starter_code/app.py:545]
2020-05-25 15:44:02,751 INFO: errors [in /Users/nisp78/Desktop/01_fyyur/starter_code/app.py:545]
2020-05-25 15:52:22,842 INFO: errors [in /Users/nisp78/Desktop/01_fyyur/starter_code/app.py:545]
2020-05-25 15:53:01,301 INFO: errors [in /Users/nisp78/Desktop/01_fyyur/starter_code/app.py:545]
2020-05-25 15:53:40,506 INFO: errors [in /Users/nisp78/Desktop/01_fyyur/starter_code/app.py:545]
2020-05-25 16:00:43,660 INFO: errors [in /Users/nisp78/Desktop/01_fyyur/starter_code/app.py:545]
2020-05-25 16:01:45,852 INFO: errors [in /Users/nisp78/Desktop/01_fyyur/starter_code/app.py:545]
2020-05-25 16:02:09,859 INFO: errors [in /Users/nisp78/Desktop/01_fyyur/starter_code/app.py:545]
2020-05-25 16:30:04,822 INFO: errors [in /Users/nisp78/Desktop/01_fyyur/starter_code/app.py:545]
2020-05-25 16:30:41,546 INFO: errors [in /Users/nisp78/Desktop/01_fyyur/starter_code/app.py:545]
2020-05-25 16:38:55,116 INFO: errors [in /Users/nisp78/Desktop/01_fyyur/starter_code/app.py:545]
2020-05-25 16:39:29,762 INFO: errors [in /Users/nisp78/Desktop/01_fyyur/starter_code/app.py:545]
2020-05-25 16:40:11,676 INFO: errors [in /Users/nisp78/Desktop/01_fyyur/starter_code/app.py:545]
2020-05-25 16:40:31,055 INFO: errors [in /Users/nisp78/Desktop/01_fyyur/starter_code/app.py:545]
2020-05-26 09:24:38,923 INFO: errors [in /Users/nisp78/Desktop/01_fyyur/starter_code/app.py:545]
2020-05-26 09:25:18,394 INFO: errors [in /Users/nisp78/Desktop/01_fyyur/starter_code/app.py:545]
2020-05-26 09:25:31,692 INFO: errors [in /Users/nisp78/Desktop/01_fyyur/starter_code/app.py:545]
2020-05-31 23:33:49,107 INFO: errors [in app.py:616]
2020-06-01 15:41:08,438 INFO: errors [in app.py:616]
2020-06-01 15:45:39,758 ERROR: Exception on /venues [GET] [in /Library/Frameworks/Python.framework/Versions/3.8/lib/python3.8/site-packages/flask/app.py:1891]
Traceback (most recent call last):
  File "/Library/Frameworks/Python.framework/Versions/3.8/lib/python3.8/site-packages/flask/app.py", line 2447, in wsgi_app
    response = self.full_dispatch_request()
  File "/Library/Frameworks/Python.framework/Versions/3.8/lib/python3.8/site-packages/flask/app.py", line 1952, in full_dispatch_request
    rv = self.handle_user_exception(e)
  File "/Library/Frameworks/Python.framework/Versions/3.8/lib/python3.8/site-packages/flask/app.py", line 1821, in handle_user_exception
    reraise(exc_type, exc_value, tb)
  File "/Library/Frameworks/Python.framework/Versions/3.8/lib/python3.8/site-packages/flask/_compat.py", line 39, in reraise
    raise value
  File "/Library/Frameworks/Python.framework/Versions/3.8/lib/python3.8/site-packages/flask/app.py", line 1950, in full_dispatch_request
    rv = self.dispatch_request()
  File "/Library/Frameworks/Python.framework/Versions/3.8/lib/python3.8/site-packages/flask/app.py", line 1936, in dispatch_request
    return self.view_functions[rule.endpoint](**req.view_args)
  File "app.py", line 144, in venues
    upcoming_shows = venue.shows.filter(Show.start_time > current_time).all()
AttributeError: 'Venue' object has no attribute 'shows'
2020-06-01 15:45:57,679 ERROR: Exception on /artists/1 [GET] [in /Library/Frameworks/Python.framework/Versions/3.8/lib/python3.8/site-packages/flask/app.py:1891]
Traceback (most recent call last):
  File "/Library/Frameworks/Python.framework/Versions/3.8/lib/python3.8/site-packages/flask/app.py", line 2447, in wsgi_app
    response = self.full_dispatch_request()
  File "/Library/Frameworks/Python.framework/Versions/3.8/lib/python3.8/site-packages/flask/app.py", line 1953, in full_dispatch_request
    return self.finalize_request(rv)
  File "/Library/Frameworks/Python.framework/Versions/3.8/lib/python3.8/site-packages/flask/app.py", line 1968, in finalize_request
    response = self.make_response(rv)
  File "/Library/Frameworks/Python.framework/Versions/3.8/lib/python3.8/site-packages/flask/app.py", line 2097, in make_response
    raise TypeError(
TypeError: The view function did not return a valid response. The function either returned None or ended without a return statement.
2020-06-01 15:46:05,992 ERROR: Exception on /venues [GET] [in /Library/Frameworks/Python.framework/Versions/3.8/lib/python3.8/site-packages/flask/app.py:1891]
Traceback (most recent call last):
  File "/Library/Frameworks/Python.framework/Versions/3.8/lib/python3.8/site-packages/flask/app.py", line 2447, in wsgi_app
    response = self.full_dispatch_request()
  File "/Library/Frameworks/Python.framework/Versions/3.8/lib/python3.8/site-packages/flask/app.py", line 1952, in full_dispatch_request
    rv = self.handle_user_exception(e)
  File "/Library/Frameworks/Python.framework/Versions/3.8/lib/python3.8/site-packages/flask/app.py", line 1821, in handle_user_exception
    reraise(exc_type, exc_value, tb)
  File "/Library/Frameworks/Python.framework/Versions/3.8/lib/python3.8/site-packages/flask/_compat.py", line 39, in reraise
    raise value
  File "/Library/Frameworks/Python.framework/Versions/3.8/lib/python3.8/site-packages/flask/app.py", line 1950, in full_dispatch_request
    rv = self.dispatch_request()
  File "/Library/Frameworks/Python.framework/Versions/3.8/lib/python3.8/site-packages/flask/app.py", line 1936, in dispatch_request
    return self.view_functions[rule.endpoint](**req.view_args)
  File "app.py", line 144, in venues
    upcoming_shows = venue.shows.filter(Show.start_time > current_time).all()
AttributeError: 'Venue' object has no attribute 'shows'
2020-06-01 15:46:10,009 ERROR: Exception on /venues [GET] [in /Library/Frameworks/Python.framework/Versions/3.8/lib/python3.8/site-packages/flask/app.py:1891]
Traceback (most recent call last):
  File "/Library/Frameworks/Python.framework/Versions/3.8/lib/python3.8/site-packages/flask/app.py", line 2447, in wsgi_app
    response = self.full_dispatch_request()
  File "/Library/Frameworks/Python.framework/Versions/3.8/lib/python3.8/site-packages/flask/app.py", line 1952, in full_dispatch_request
    rv = self.handle_user_exception(e)
  File "/Library/Frameworks/Python.framework/Versions/3.8/lib/python3.8/site-packages/flask/app.py", line 1821, in handle_user_exception
    reraise(exc_type, exc_value, tb)
  File "/Library/Frameworks/Python.framework/Versions/3.8/lib/python3.8/site-packages/flask/_compat.py", line 39, in reraise
    raise value
  File "/Library/Frameworks/Python.framework/Versions/3.8/lib/python3.8/site-packages/flask/app.py", line 1950, in full_dispatch_request
    rv = self.dispatch_request()
  File "/Library/Frameworks/Python.framework/Versions/3.8/lib/python3.8/site-packages/flask/app.py", line 1936, in dispatch_request
    return self.view_functions[rule.endpoint](**req.view_args)
  File "app.py", line 144, in venues
    upcoming_shows = venue.shows.filter(Show.start_time > current_time).all()
AttributeError: 'Venue' object has no attribute 'shows'
2020-06-01 15:46:13,686 ERROR: Exception on /venues/create [GET] [in /Library/Frameworks/Python.framework/Versions/3.8/lib/python3.8/site-packages/flask/app.py:1891]
Traceback (most recent call last):
  File "/Library/Frameworks/Python.framework/Versions/3.8/lib/python3.8/site-packages/flask/app.py", line 2447, in wsgi_app
    response = self.full_dispatch_request()
  File "/Library/Frameworks/Python.framework/Versions/3.8/lib/python3.8/site-packages/flask/app.py", line 1952, in full_dispatch_request
    rv = self.handle_user_exception(e)
  File "/Library/Frameworks/Python.framework/Versions/3.8/lib/python3.8/site-packages/flask/app.py", line 1821, in handle_user_exception
    reraise(exc_type, exc_value, tb)
  File "/Library/Frameworks/Python.framework/Versions/3.8/lib/python3.8/site-packages/flask/_compat.py", line 39, in reraise
    raise value
  File "/Library/Frameworks/Python.framework/Versions/3.8/lib/python3.8/site-packages/flask/app.py", line 1950, in full_dispatch_request
    rv = self.dispatch_request()
  File "/Library/Frameworks/Python.framework/Versions/3.8/lib/python3.8/site-packages/flask/app.py", line 1936, in dispatch_request
    return self.view_functions[rule.endpoint](**req.view_args)
  File "app.py", line 226, in create_venue_form
    form = VenueForm()
  File "/Library/Frameworks/Python.framework/Versions/3.8/lib/python3.8/site-packages/wtforms/form.py", line 208, in __call__
    return type.__call__(cls, *args, **kwargs)
  File "/Library/Frameworks/Python.framework/Versions/3.8/lib/python3.8/site-packages/flask_wtf/form.py", line 157, in __init__
    super(Form, self).__init__(*args, **kwargs)
  File "/Library/Frameworks/Python.framework/Versions/3.8/lib/python3.8/site-packages/flask_wtf/form.py", line 87, in __init__
    super(FlaskForm, self).__init__(formdata=formdata, **kwargs)
  File "/Library/Frameworks/Python.framework/Versions/3.8/lib/python3.8/site-packages/wtforms/form.py", line 274, in __init__
    self.process(formdata, obj, data=data, **kwargs)
  File "/Library/Frameworks/Python.framework/Versions/3.8/lib/python3.8/site-packages/wtforms/form.py", line 131, in process
    field.process(formdata)
  File "/Library/Frameworks/Python.framework/Versions/3.8/lib/python3.8/site-packages/wtforms/csrf/core.py", line 43, in process
    self.current_token = self.csrf_impl.generate_csrf_token(self)
  File "/Library/Frameworks/Python.framework/Versions/3.8/lib/python3.8/site-packages/flask_wtf/csrf.py", line 139, in generate_csrf_token
    return generate_csrf(
  File "/Library/Frameworks/Python.framework/Versions/3.8/lib/python3.8/site-packages/flask_wtf/csrf.py", line 33, in generate_csrf
    secret_key = _get_config(
  File "/Library/Frameworks/Python.framework/Versions/3.8/lib/python3.8/site-packages/flask_wtf/csrf.py", line 128, in _get_config
    raise RuntimeError(message)
RuntimeError: A secret key is required to use CSRF.
2020-06-01 15:46:23,679 ERROR: Exception on /artists/1 [GET] [in /Library/Frameworks/Python.framework/Versions/3.8/lib/python3.8/site-packages/flask/app.py:1891]
Traceback (most recent call last):
  File "/Library/Frameworks/Python.framework/Versions/3.8/lib/python3.8/site-packages/flask/app.py", line 2447, in wsgi_app
    response = self.full_dispatch_request()
  File "/Library/Frameworks/Python.framework/Versions/3.8/lib/python3.8/site-packages/flask/app.py", line 1953, in full_dispatch_request
    return self.finalize_request(rv)
  File "/Library/Frameworks/Python.framework/Versions/3.8/lib/python3.8/site-packages/flask/app.py", line 1968, in finalize_request
    response = self.make_response(rv)
  File "/Library/Frameworks/Python.framework/Versions/3.8/lib/python3.8/site-packages/flask/app.py", line 2097, in make_response
    raise TypeError(
TypeError: The view function did not return a valid response. The function either returned None or ended without a return statement.
2020-06-01 15:46:28,570 ERROR: Exception on /artists/create [GET] [in /Library/Frameworks/Python.framework/Versions/3.8/lib/python3.8/site-packages/flask/app.py:1891]
Traceback (most recent call last):
  File "/Library/Frameworks/Python.framework/Versions/3.8/lib/python3.8/site-packages/flask/app.py", line 2447, in wsgi_app
    response = self.full_dispatch_request()
  File "/Library/Frameworks/Python.framework/Versions/3.8/lib/python3.8/site-packages/flask/app.py", line 1952, in full_dispatch_request
    rv = self.handle_user_exception(e)
  File "/Library/Frameworks/Python.framework/Versions/3.8/lib/python3.8/site-packages/flask/app.py", line 1821, in handle_user_exception
    reraise(exc_type, exc_value, tb)
  File "/Library/Frameworks/Python.framework/Versions/3.8/lib/python3.8/site-packages/flask/_compat.py", line 39, in reraise
    raise value
  File "/Library/Frameworks/Python.framework/Versions/3.8/lib/python3.8/site-packages/flask/app.py", line 1950, in full_dispatch_request
    rv = self.dispatch_request()
  File "/Library/Frameworks/Python.framework/Versions/3.8/lib/python3.8/site-packages/flask/app.py", line 1936, in dispatch_request
    return self.view_functions[rule.endpoint](**req.view_args)
  File "app.py", line 507, in create_artist_form
    form = ArtistForm()
  File "/Library/Frameworks/Python.framework/Versions/3.8/lib/python3.8/site-packages/wtforms/form.py", line 208, in __call__
    return type.__call__(cls, *args, **kwargs)
  File "/Library/Frameworks/Python.framework/Versions/3.8/lib/python3.8/site-packages/flask_wtf/form.py", line 157, in __init__
    super(Form, self).__init__(*args, **kwargs)
  File "/Library/Frameworks/Python.framework/Versions/3.8/lib/python3.8/site-packages/flask_wtf/form.py", line 87, in __init__
    super(FlaskForm, self).__init__(formdata=formdata, **kwargs)
  File "/Library/Frameworks/Python.framework/Versions/3.8/lib/python3.8/site-packages/wtforms/form.py", line 274, in __init__
    self.process(formdata, obj, data=data, **kwargs)
  File "/Library/Frameworks/Python.framework/Versions/3.8/lib/python3.8/site-packages/wtforms/form.py", line 131, in process
    field.process(formdata)
  File "/Library/Frameworks/Python.framework/Versions/3.8/lib/python3.8/site-packages/wtforms/csrf/core.py", line 43, in process
    self.current_token = self.csrf_impl.generate_csrf_token(self)
  File "/Library/Frameworks/Python.framework/Versions/3.8/lib/python3.8/site-packages/flask_wtf/csrf.py", line 139, in generate_csrf_token
    return generate_csrf(
  File "/Library/Frameworks/Python.framework/Versions/3.8/lib/python3.8/site-packages/flask_wtf/csrf.py", line 33, in generate_csrf
    secret_key = _get_config(
  File "/Library/Frameworks/Python.framework/Versions/3.8/lib/python3.8/site-packages/flask_wtf/csrf.py", line 128, in _get_config
    raise RuntimeError(message)
RuntimeError: A secret key is required to use CSRF.
2020-06-01 15:46:31,902 ERROR: Exception on /venues [GET] [in /Library/Frameworks/Python.framework/Versions/3.8/lib/python3.8/site-packages/flask/app.py:1891]
Traceback (most recent call last):
  File "/Library/Frameworks/Python.framework/Versions/3.8/lib/python3.8/site-packages/flask/app.py", line 2447, in wsgi_app
    response = self.full_dispatch_request()
  File "/Library/Frameworks/Python.framework/Versions/3.8/lib/python3.8/site-packages/flask/app.py", line 1952, in full_dispatch_request
    rv = self.handle_user_exception(e)
  File "/Library/Frameworks/Python.framework/Versions/3.8/lib/python3.8/site-packages/flask/app.py", line 1821, in handle_user_exception
    reraise(exc_type, exc_value, tb)
  File "/Library/Frameworks/Python.framework/Versions/3.8/lib/python3.8/site-packages/flask/_compat.py", line 39, in reraise
    raise value
  File "/Library/Frameworks/Python.framework/Versions/3.8/lib/python3.8/site-packages/flask/app.py", line 1950, in full_dispatch_request
    rv = self.dispatch_request()
  File "/Library/Frameworks/Python.framework/Versions/3.8/lib/python3.8/site-packages/flask/app.py", line 1936, in dispatch_request
    return self.view_functions[rule.endpoint](**req.view_args)
  File "app.py", line 144, in venues
    upcoming_shows = venue.shows.filter(Show.start_time > current_time).all()
AttributeError: 'Venue' object has no attribute 'shows'
2020-06-01 15:48:16,396 ERROR: Exception on /venues [GET] [in /Library/Frameworks/Python.framework/Versions/3.8/lib/python3.8/site-packages/flask/app.py:1891]
Traceback (most recent call last):
  File "/Library/Frameworks/Python.framework/Versions/3.8/lib/python3.8/site-packages/flask/app.py", line 2447, in wsgi_app
    response = self.full_dispatch_request()
  File "/Library/Frameworks/Python.framework/Versions/3.8/lib/python3.8/site-packages/flask/app.py", line 1952, in full_dispatch_request
    rv = self.handle_user_exception(e)
  File "/Library/Frameworks/Python.framework/Versions/3.8/lib/python3.8/site-packages/flask/app.py", line 1821, in handle_user_exception
    reraise(exc_type, exc_value, tb)
  File "/Library/Frameworks/Python.framework/Versions/3.8/lib/python3.8/site-packages/flask/_compat.py", line 39, in reraise
    raise value
  File "/Library/Frameworks/Python.framework/Versions/3.8/lib/python3.8/site-packages/flask/app.py", line 1950, in full_dispatch_request
    rv = self.dispatch_request()
  File "/Library/Frameworks/Python.framework/Versions/3.8/lib/python3.8/site-packages/flask/app.py", line 1936, in dispatch_request
    return self.view_functions[rule.endpoint](**req.view_args)
  File "app.py", line 144, in venues
    upcoming_shows = venue.shows.filter(Show.start_time > current_time).all()
AttributeError: 'Venue' object has no attribute 'shows'
2020-06-01 15:59:49,380 ERROR: Exception on /venues [GET] [in /Library/Frameworks/Python.framework/Versions/3.8/lib/python3.8/site-packages/flask/app.py:1891]
Traceback (most recent call last):
  File "/Library/Frameworks/Python.framework/Versions/3.8/lib/python3.8/site-packages/flask/app.py", line 2447, in wsgi_app
    response = self.full_dispatch_request()
  File "/Library/Frameworks/Python.framework/Versions/3.8/lib/python3.8/site-packages/flask/app.py", line 1952, in full_dispatch_request
    rv = self.handle_user_exception(e)
  File "/Library/Frameworks/Python.framework/Versions/3.8/lib/python3.8/site-packages/flask/app.py", line 1821, in handle_user_exception
    reraise(exc_type, exc_value, tb)
  File "/Library/Frameworks/Python.framework/Versions/3.8/lib/python3.8/site-packages/flask/_compat.py", line 39, in reraise
    raise value
  File "/Library/Frameworks/Python.framework/Versions/3.8/lib/python3.8/site-packages/flask/app.py", line 1950, in full_dispatch_request
    rv = self.dispatch_request()
  File "/Library/Frameworks/Python.framework/Versions/3.8/lib/python3.8/site-packages/flask/app.py", line 1936, in dispatch_request
    return self.view_functions[rule.endpoint](**req.view_args)
  File "app.py", line 144, in venues
    upcoming_shows = venue.shows.filter(Show.start_time > current_time).all()
AttributeError: 'Venue' object has no attribute 'shows'
2020-06-01 15:59:54,453 ERROR: Exception on /artists/1 [GET] [in /Library/Frameworks/Python.framework/Versions/3.8/lib/python3.8/site-packages/flask/app.py:1891]
Traceback (most recent call last):
  File "/Library/Frameworks/Python.framework/Versions/3.8/lib/python3.8/site-packages/flask/app.py", line 2447, in wsgi_app
    response = self.full_dispatch_request()
  File "/Library/Frameworks/Python.framework/Versions/3.8/lib/python3.8/site-packages/flask/app.py", line 1953, in full_dispatch_request
    return self.finalize_request(rv)
  File "/Library/Frameworks/Python.framework/Versions/3.8/lib/python3.8/site-packages/flask/app.py", line 1968, in finalize_request
    response = self.make_response(rv)
  File "/Library/Frameworks/Python.framework/Versions/3.8/lib/python3.8/site-packages/flask/app.py", line 2097, in make_response
    raise TypeError(
TypeError: The view function did not return a valid response. The function either returned None or ended without a return statement.
2020-06-01 16:00:00,066 ERROR: Exception on /shows/create [GET] [in /Library/Frameworks/Python.framework/Versions/3.8/lib/python3.8/site-packages/flask/app.py:1891]
Traceback (most recent call last):
  File "/Library/Frameworks/Python.framework/Versions/3.8/lib/python3.8/site-packages/flask/app.py", line 2447, in wsgi_app
    response = self.full_dispatch_request()
  File "/Library/Frameworks/Python.framework/Versions/3.8/lib/python3.8/site-packages/flask/app.py", line 1952, in full_dispatch_request
    rv = self.handle_user_exception(e)
  File "/Library/Frameworks/Python.framework/Versions/3.8/lib/python3.8/site-packages/flask/app.py", line 1821, in handle_user_exception
    reraise(exc_type, exc_value, tb)
  File "/Library/Frameworks/Python.framework/Versions/3.8/lib/python3.8/site-packages/flask/_compat.py", line 39, in reraise
    raise value
  File "/Library/Frameworks/Python.framework/Versions/3.8/lib/python3.8/site-packages/flask/app.py", line 1950, in full_dispatch_request
    rv = self.dispatch_request()
  File "/Library/Frameworks/Python.framework/Versions/3.8/lib/python3.8/site-packages/flask/app.py", line 1936, in dispatch_request
    return self.view_functions[rule.endpoint](**req.view_args)
  File "app.py", line 577, in create_shows
    def create_shows():
  File "/Library/Frameworks/Python.framework/Versions/3.8/lib/python3.8/site-packages/wtforms/form.py", line 208, in __call__
    return type.__call__(cls, *args, **kwargs)
  File "/Library/Frameworks/Python.framework/Versions/3.8/lib/python3.8/site-packages/flask_wtf/form.py", line 157, in __init__
    super(Form, self).__init__(*args, **kwargs)
  File "/Library/Frameworks/Python.framework/Versions/3.8/lib/python3.8/site-packages/flask_wtf/form.py", line 87, in __init__
    super(FlaskForm, self).__init__(formdata=formdata, **kwargs)
  File "/Library/Frameworks/Python.framework/Versions/3.8/lib/python3.8/site-packages/wtforms/form.py", line 274, in __init__
    self.process(formdata, obj, data=data, **kwargs)
  File "/Library/Frameworks/Python.framework/Versions/3.8/lib/python3.8/site-packages/wtforms/form.py", line 131, in process
    field.process(formdata)
  File "/Library/Frameworks/Python.framework/Versions/3.8/lib/python3.8/site-packages/wtforms/csrf/core.py", line 43, in process
    self.current_token = self.csrf_impl.generate_csrf_token(self)
  File "/Library/Frameworks/Python.framework/Versions/3.8/lib/python3.8/site-packages/flask_wtf/csrf.py", line 139, in generate_csrf_token
    return generate_csrf(
  File "/Library/Frameworks/Python.framework/Versions/3.8/lib/python3.8/site-packages/flask_wtf/csrf.py", line 33, in generate_csrf
    secret_key = _get_config(
  File "/Library/Frameworks/Python.framework/Versions/3.8/lib/python3.8/site-packages/flask_wtf/csrf.py", line 128, in _get_config
    raise RuntimeError(message)
RuntimeError: A secret key is required to use CSRF.
2020-06-01 16:00:06,343 ERROR: Exception on /artists/create [GET] [in /Library/Frameworks/Python.framework/Versions/3.8/lib/python3.8/site-packages/flask/app.py:1891]
Traceback (most recent call last):
  File "/Library/Frameworks/Python.framework/Versions/3.8/lib/python3.8/site-packages/flask/app.py", line 2447, in wsgi_app
    response = self.full_dispatch_request()
  File "/Library/Frameworks/Python.framework/Versions/3.8/lib/python3.8/site-packages/flask/app.py", line 1952, in full_dispatch_request
    rv = self.handle_user_exception(e)
  File "/Library/Frameworks/Python.framework/Versions/3.8/lib/python3.8/site-packages/flask/app.py", line 1821, in handle_user_exception
    reraise(exc_type, exc_value, tb)
  File "/Library/Frameworks/Python.framework/Versions/3.8/lib/python3.8/site-packages/flask/_compat.py", line 39, in reraise
    raise value
  File "/Library/Frameworks/Python.framework/Versions/3.8/lib/python3.8/site-packages/flask/app.py", line 1950, in full_dispatch_request
    rv = self.dispatch_request()
  File "/Library/Frameworks/Python.framework/Versions/3.8/lib/python3.8/site-packages/flask/app.py", line 1936, in dispatch_request
    return self.view_functions[rule.endpoint](**req.view_args)
  File "app.py", line 507, in create_artist_form
    def create_artist_form():
  File "/Library/Frameworks/Python.framework/Versions/3.8/lib/python3.8/site-packages/wtforms/form.py", line 208, in __call__
    return type.__call__(cls, *args, **kwargs)
  File "/Library/Frameworks/Python.framework/Versions/3.8/lib/python3.8/site-packages/flask_wtf/form.py", line 157, in __init__
    super(Form, self).__init__(*args, **kwargs)
  File "/Library/Frameworks/Python.framework/Versions/3.8/lib/python3.8/site-packages/flask_wtf/form.py", line 87, in __init__
    super(FlaskForm, self).__init__(formdata=formdata, **kwargs)
  File "/Library/Frameworks/Python.framework/Versions/3.8/lib/python3.8/site-packages/wtforms/form.py", line 274, in __init__
    self.process(formdata, obj, data=data, **kwargs)
  File "/Library/Frameworks/Python.framework/Versions/3.8/lib/python3.8/site-packages/wtforms/form.py", line 131, in process
    field.process(formdata)
  File "/Library/Frameworks/Python.framework/Versions/3.8/lib/python3.8/site-packages/wtforms/csrf/core.py", line 43, in process
    self.current_token = self.csrf_impl.generate_csrf_token(self)
  File "/Library/Frameworks/Python.framework/Versions/3.8/lib/python3.8/site-packages/flask_wtf/csrf.py", line 139, in generate_csrf_token
    return generate_csrf(
  File "/Library/Frameworks/Python.framework/Versions/3.8/lib/python3.8/site-packages/flask_wtf/csrf.py", line 33, in generate_csrf
    secret_key = _get_config(
  File "/Library/Frameworks/Python.framework/Versions/3.8/lib/python3.8/site-packages/flask_wtf/csrf.py", line 128, in _get_config
    raise RuntimeError(message)
RuntimeError: A secret key is required to use CSRF.
2020-06-01 16:00:09,484 ERROR: Exception on /venues [GET] [in /Library/Frameworks/Python.framework/Versions/3.8/lib/python3.8/site-packages/flask/app.py:1891]
Traceback (most recent call last):
  File "/Library/Frameworks/Python.framework/Versions/3.8/lib/python3.8/site-packages/flask/app.py", line 2447, in wsgi_app
    response = self.full_dispatch_request()
  File "/Library/Frameworks/Python.framework/Versions/3.8/lib/python3.8/site-packages/flask/app.py", line 1952, in full_dispatch_request
    rv = self.handle_user_exception(e)
  File "/Library/Frameworks/Python.framework/Versions/3.8/lib/python3.8/site-packages/flask/app.py", line 1821, in handle_user_exception
    reraise(exc_type, exc_value, tb)
  File "/Library/Frameworks/Python.framework/Versions/3.8/lib/python3.8/site-packages/flask/_compat.py", line 39, in reraise
    raise value
  File "/Library/Frameworks/Python.framework/Versions/3.8/lib/python3.8/site-packages/flask/app.py", line 1950, in full_dispatch_request
    rv = self.dispatch_request()
  File "/Library/Frameworks/Python.framework/Versions/3.8/lib/python3.8/site-packages/flask/app.py", line 1936, in dispatch_request
    return self.view_functions[rule.endpoint](**req.view_args)
  File "app.py", line 144, in venues
    upcoming_shows = venue.shows.filter(Show.start_time > current_time).all()
AttributeError: 'Venue' object has no attribute 'shows'
2020-06-01 16:00:11,372 ERROR: Exception on /venues/create [GET] [in /Library/Frameworks/Python.framework/Versions/3.8/lib/python3.8/site-packages/flask/app.py:1891]
Traceback (most recent call last):
  File "/Library/Frameworks/Python.framework/Versions/3.8/lib/python3.8/site-packages/flask/app.py", line 2447, in wsgi_app
    response = self.full_dispatch_request()
  File "/Library/Frameworks/Python.framework/Versions/3.8/lib/python3.8/site-packages/flask/app.py", line 1952, in full_dispatch_request
    rv = self.handle_user_exception(e)
  File "/Library/Frameworks/Python.framework/Versions/3.8/lib/python3.8/site-packages/flask/app.py", line 1821, in handle_user_exception
    reraise(exc_type, exc_value, tb)
  File "/Library/Frameworks/Python.framework/Versions/3.8/lib/python3.8/site-packages/flask/_compat.py", line 39, in reraise
    raise value
  File "/Library/Frameworks/Python.framework/Versions/3.8/lib/python3.8/site-packages/flask/app.py", line 1950, in full_dispatch_request
    rv = self.dispatch_request()
  File "/Library/Frameworks/Python.framework/Versions/3.8/lib/python3.8/site-packages/flask/app.py", line 1936, in dispatch_request
    return self.view_functions[rule.endpoint](**req.view_args)
  File "app.py", line 226, in create_venue_form
    def create_venue_form():
  File "/Library/Frameworks/Python.framework/Versions/3.8/lib/python3.8/site-packages/wtforms/form.py", line 208, in __call__
    return type.__call__(cls, *args, **kwargs)
  File "/Library/Frameworks/Python.framework/Versions/3.8/lib/python3.8/site-packages/flask_wtf/form.py", line 157, in __init__
    super(Form, self).__init__(*args, **kwargs)
  File "/Library/Frameworks/Python.framework/Versions/3.8/lib/python3.8/site-packages/flask_wtf/form.py", line 87, in __init__
    super(FlaskForm, self).__init__(formdata=formdata, **kwargs)
  File "/Library/Frameworks/Python.framework/Versions/3.8/lib/python3.8/site-packages/wtforms/form.py", line 274, in __init__
    self.process(formdata, obj, data=data, **kwargs)
  File "/Library/Frameworks/Python.framework/Versions/3.8/lib/python3.8/site-packages/wtforms/form.py", line 131, in process
    field.process(formdata)
  File "/Library/Frameworks/Python.framework/Versions/3.8/lib/python3.8/site-packages/wtforms/csrf/core.py", line 43, in process
    self.current_token = self.csrf_impl.generate_csrf_token(self)
  File "/Library/Frameworks/Python.framework/Versions/3.8/lib/python3.8/site-packages/flask_wtf/csrf.py", line 139, in generate_csrf_token
    return generate_csrf(
  File "/Library/Frameworks/Python.framework/Versions/3.8/lib/python3.8/site-packages/flask_wtf/csrf.py", line 33, in generate_csrf
    secret_key = _get_config(
  File "/Library/Frameworks/Python.framework/Versions/3.8/lib/python3.8/site-packages/flask_wtf/csrf.py", line 128, in _get_config
    raise RuntimeError(message)
RuntimeError: A secret key is required to use CSRF.
2020-06-01 16:00:36,137 ERROR: Exception on /artists/1 [GET] [in /Library/Frameworks/Python.framework/Versions/3.8/lib/python3.8/site-packages/flask/app.py:1891]
Traceback (most recent call last):
  File "/Library/Frameworks/Python.framework/Versions/3.8/lib/python3.8/site-packages/flask/app.py", line 2447, in wsgi_app
    response = self.full_dispatch_request()
  File "/Library/Frameworks/Python.framework/Versions/3.8/lib/python3.8/site-packages/flask/app.py", line 1953, in full_dispatch_request
    return self.finalize_request(rv)
  File "/Library/Frameworks/Python.framework/Versions/3.8/lib/python3.8/site-packages/flask/app.py", line 1968, in finalize_request
    response = self.make_response(rv)
  File "/Library/Frameworks/Python.framework/Versions/3.8/lib/python3.8/site-packages/flask/app.py", line 2097, in make_response
    raise TypeError(
TypeError: The view function did not return a valid response. The function either returned None or ended without a return statement.
2020-06-01 16:01:06,198 ERROR: Exception on /artists/1 [GET] [in /Library/Frameworks/Python.framework/Versions/3.8/lib/python3.8/site-packages/flask/app.py:1891]
Traceback (most recent call last):
  File "/Library/Frameworks/Python.framework/Versions/3.8/lib/python3.8/site-packages/flask/app.py", line 2447, in wsgi_app
    response = self.full_dispatch_request()
  File "/Library/Frameworks/Python.framework/Versions/3.8/lib/python3.8/site-packages/flask/app.py", line 1953, in full_dispatch_request
    return self.finalize_request(rv)
  File "/Library/Frameworks/Python.framework/Versions/3.8/lib/python3.8/site-packages/flask/app.py", line 1968, in finalize_request
    response = self.make_response(rv)
  File "/Library/Frameworks/Python.framework/Versions/3.8/lib/python3.8/site-packages/flask/app.py", line 2097, in make_response
    raise TypeError(
TypeError: The view function did not return a valid response. The function either returned None or ended without a return statement.
2020-06-01 16:01:13,712 ERROR: Exception on /venues [GET] [in /Library/Frameworks/Python.framework/Versions/3.8/lib/python3.8/site-packages/flask/app.py:1891]
Traceback (most recent call last):
  File "/Library/Frameworks/Python.framework/Versions/3.8/lib/python3.8/site-packages/flask/app.py", line 2447, in wsgi_app
    response = self.full_dispatch_request()
  File "/Library/Frameworks/Python.framework/Versions/3.8/lib/python3.8/site-packages/flask/app.py", line 1952, in full_dispatch_request
    rv = self.handle_user_exception(e)
  File "/Library/Frameworks/Python.framework/Versions/3.8/lib/python3.8/site-packages/flask/app.py", line 1821, in handle_user_exception
    reraise(exc_type, exc_value, tb)
  File "/Library/Frameworks/Python.framework/Versions/3.8/lib/python3.8/site-packages/flask/_compat.py", line 39, in reraise
    raise value
  File "/Library/Frameworks/Python.framework/Versions/3.8/lib/python3.8/site-packages/flask/app.py", line 1950, in full_dispatch_request
    rv = self.dispatch_request()
  File "/Library/Frameworks/Python.framework/Versions/3.8/lib/python3.8/site-packages/flask/app.py", line 1936, in dispatch_request
    return self.view_functions[rule.endpoint](**req.view_args)
  File "app.py", line 144, in venues
    upcoming_shows = venue.shows.filter(Show.start_time > current_time).all()
AttributeError: 'Venue' object has no attribute 'shows'
2020-06-01 16:41:08,883 INFO: errors [in app.py:604]
2020-06-01 16:41:35,902 ERROR: Exception on /venues/1 [GET] [in /Library/Frameworks/Python.framework/Versions/3.8/lib/python3.8/site-packages/flask/app.py:1891]
Traceback (most recent call last):
  File "/Library/Frameworks/Python.framework/Versions/3.8/lib/python3.8/site-packages/flask/app.py", line 2447, in wsgi_app
    response = self.full_dispatch_request()
  File "/Library/Frameworks/Python.framework/Versions/3.8/lib/python3.8/site-packages/flask/app.py", line 1953, in full_dispatch_request
    return self.finalize_request(rv)
  File "/Library/Frameworks/Python.framework/Versions/3.8/lib/python3.8/site-packages/flask/app.py", line 1968, in finalize_request
    response = self.make_response(rv)
  File "/Library/Frameworks/Python.framework/Versions/3.8/lib/python3.8/site-packages/flask/app.py", line 2097, in make_response
    raise TypeError(
TypeError: The view function did not return a valid response. The function either returned None or ended without a return statement.
2020-06-01 16:41:41,889 ERROR: Exception on /artists/1 [GET] [in /Library/Frameworks/Python.framework/Versions/3.8/lib/python3.8/site-packages/flask/app.py:1891]
Traceback (most recent call last):
  File "/Library/Frameworks/Python.framework/Versions/3.8/lib/python3.8/site-packages/flask/app.py", line 2447, in wsgi_app
    response = self.full_dispatch_request()
  File "/Library/Frameworks/Python.framework/Versions/3.8/lib/python3.8/site-packages/flask/app.py", line 1953, in full_dispatch_request
    return self.finalize_request(rv)
  File "/Library/Frameworks/Python.framework/Versions/3.8/lib/python3.8/site-packages/flask/app.py", line 1968, in finalize_request
    response = self.make_response(rv)
  File "/Library/Frameworks/Python.framework/Versions/3.8/lib/python3.8/site-packages/flask/app.py", line 2097, in make_response
    raise TypeError(
TypeError: The view function did not return a valid response. The function either returned None or ended without a return statement.
2020-06-01 17:03:56,473 INFO: errors [in /Users/nisp78/Desktop/01_fyyur/starter_code/app.py:617]
2020-06-01 17:05:25,267 INFO: errors [in app.py:617]
2020-06-01 17:05:54,289 INFO: errors [in app.py:617]
2020-06-01 17:07:46,466 INFO: errors [in app.py:617]
2020-06-01 17:10:10,638 INFO: errors [in app.py:617]
2020-06-01 17:30:54,434 INFO: errors [in app.py:617]
2020-06-01 17:31:46,069 ERROR: Exception on /venues [GET] [in /Library/Frameworks/Python.framework/Versions/3.8/lib/python3.8/site-packages/flask/app.py:1891]
Traceback (most recent call last):
  File "/Library/Frameworks/Python.framework/Versions/3.8/lib/python3.8/site-packages/flask/app.py", line 2447, in wsgi_app
    response = self.full_dispatch_request()
  File "/Library/Frameworks/Python.framework/Versions/3.8/lib/python3.8/site-packages/flask/app.py", line 1952, in full_dispatch_request
    rv = self.handle_user_exception(e)
  File "/Library/Frameworks/Python.framework/Versions/3.8/lib/python3.8/site-packages/flask/app.py", line 1821, in handle_user_exception
    reraise(exc_type, exc_value, tb)
  File "/Library/Frameworks/Python.framework/Versions/3.8/lib/python3.8/site-packages/flask/_compat.py", line 39, in reraise
    raise value
  File "/Library/Frameworks/Python.framework/Versions/3.8/lib/python3.8/site-packages/flask/app.py", line 1950, in full_dispatch_request
    rv = self.dispatch_request()
  File "/Library/Frameworks/Python.framework/Versions/3.8/lib/python3.8/site-packages/flask/app.py", line 1936, in dispatch_request
    return self.view_functions[rule.endpoint](**req.view_args)
  File "app.py", line 144, in venues
    upcoming_shows = venue.shows.filter(Show.start_time > current_time).all()
AttributeError: 'InstrumentedList' object has no attribute 'filter'
2020-06-01 17:31:51,115 ERROR: Exception on /artists/1 [GET] [in /Library/Frameworks/Python.framework/Versions/3.8/lib/python3.8/site-packages/flask/app.py:1891]
Traceback (most recent call last):
  File "/Library/Frameworks/Python.framework/Versions/3.8/lib/python3.8/site-packages/flask/app.py", line 2447, in wsgi_app
    response = self.full_dispatch_request()
  File "/Library/Frameworks/Python.framework/Versions/3.8/lib/python3.8/site-packages/flask/app.py", line 1953, in full_dispatch_request
    return self.finalize_request(rv)
  File "/Library/Frameworks/Python.framework/Versions/3.8/lib/python3.8/site-packages/flask/app.py", line 1968, in finalize_request
    response = self.make_response(rv)
  File "/Library/Frameworks/Python.framework/Versions/3.8/lib/python3.8/site-packages/flask/app.py", line 2097, in make_response
    raise TypeError(
TypeError: The view function did not return a valid response. The function either returned None or ended without a return statement.
2020-06-01 17:31:55,219 ERROR: Exception on /venues [GET] [in /Library/Frameworks/Python.framework/Versions/3.8/lib/python3.8/site-packages/flask/app.py:1891]
Traceback (most recent call last):
  File "/Library/Frameworks/Python.framework/Versions/3.8/lib/python3.8/site-packages/flask/app.py", line 2447, in wsgi_app
    response = self.full_dispatch_request()
  File "/Library/Frameworks/Python.framework/Versions/3.8/lib/python3.8/site-packages/flask/app.py", line 1952, in full_dispatch_request
    rv = self.handle_user_exception(e)
  File "/Library/Frameworks/Python.framework/Versions/3.8/lib/python3.8/site-packages/flask/app.py", line 1821, in handle_user_exception
    reraise(exc_type, exc_value, tb)
  File "/Library/Frameworks/Python.framework/Versions/3.8/lib/python3.8/site-packages/flask/_compat.py", line 39, in reraise
    raise value
  File "/Library/Frameworks/Python.framework/Versions/3.8/lib/python3.8/site-packages/flask/app.py", line 1950, in full_dispatch_request
    rv = self.dispatch_request()
  File "/Library/Frameworks/Python.framework/Versions/3.8/lib/python3.8/site-packages/flask/app.py", line 1936, in dispatch_request
    return self.view_functions[rule.endpoint](**req.view_args)
  File "app.py", line 144, in venues
    upcoming_shows = venue.shows.filter(Show.start_time > current_time).all()
AttributeError: 'InstrumentedList' object has no attribute 'filter'
